Workbook

Sheet Catálogo
A1: ID | B1: Título | C1: Autor | D1: Editorial | E1: Categoría | F1: Foto | G1: Estado de lectura | H1: Ubicación | I1: Notas
A2: 1 | B2: Toulouse-Lautrec | C2: Hajo Düchting | D2: Könemann | E2: Arte | F2: 12
A3: 2 | B3: Angela Merkel | C3: Ana Carbajosa | E3: Biografías | F3: 16
A4: 3 | B4: Leonardo da Vinci: La biografía | C4: Walter Isaacson | E4: Biografías | F4: 16
A5: 4 | B5: Rubik | C5: Ernő Rubik | D5: Blackie Books | E5: Biografías | F5: 16
A6: 5 | B6: Steve Jobs: Lecciones de liderazgo | C6: Walter Isaacson | E6: Biografías | F6: 7
A7: 6 | B7: Una tierra prometida | C7: Barack Obama | E7: Biografías | F7: 16
A8: 7 | B8: Aromas del mundo | C8: Harold McGee | D8: Debate | E8: Ciencia y divulgación | F8: 14
A9: 8 | B9: El código secreto | D9: Evergreen | E9: Ciencia y divulgación | F9: 14
A10: 9 | B10: El espejismo de Dios | C10: Richard Dawkins | D10: Espasa | E10: Ciencia y divulgación | F10: 6
A11: 10 | B11: El futuro de nuestra mente | C11: Michio Kaku | D11: Debate | E11: Ciencia y divulgación | F11: 21
A12: 11 | B12: El hombre que calculaba | C12: Malba Tahan | D12: Lucemar | E12: Ciencia y divulgación | F12: 12
A13: 12 | B13: El inconcebible universo | C13: José Gordon | E13: Ciencia y divulgación | F13: 6
A14: 13 | B14: La conquista de la actualidad | C14: Steven Johnson | D14: Granica | E14: Ciencia y divulgación | F14: 6 | I14: Confirmar autor
A15: 14 | B15: La física del futuro | C15: Michio Kaku | D15: Debate | E15: Ciencia y divulgación | F15: 12
A16: 15 | B16: La magia de las matemáticas | D16: RBA | E16: Ciencia y divulgación | F16: 12
A17: 16 | B17: La proporción áurea | C17: Mario Livio | E17: Ciencia y divulgación | F17: 11
A18: 17 | B18: La singularidad está más cerca | C18: Ray Kurzweil | E18: Ciencia y divulgación | F18: 10
A19: 18 | B19: Los científicos y el mundo | C19: Robert P. Crease | D19: Crítica | E19: Ciencia y divulgación | F19: 6
A20: 19 | B20: Mentes geniales | C20: Mario de la Piedra Walter | D20: Debate | E20: Ciencia y divulgación | F20: 6
A21: 20 | B21: Nexus | C21: Yuval Noah Harari | D21: Debate | E21: Ciencia y divulgación | F21: 6
A22: 21 | B22: Odorama | C22: Federico Kukso | D22: Taurus | E22: Ciencia y divulgación | F22: 14
A23: 22 | B23: Programados para crear | C23: Marcus du Sautoy | E23: Ciencia y divulgación | F23: 18
A24: 23 | B24: Comunícate, cautiva y convence | C24: Gaby Vargas | E24: Comunicación y marca personal | F24: 9
A25: 24 | B25: Cómo ganar amigos e influir sobre las personas | C25: Dale Carnegie | E25: Comunicación y marca personal | F25: 9
A26: 25 | B26: Cómo hablar bien en público e influir sobre las personas de negocios | C26: Dale Carnegie | E26: Comunicación y marca personal | F26: 9
A27: 26 | B27: Cómo vender su marca personal | C27: Raquel Gómez H. | E27: Comunicación y marca personal | F27: 9
A28: 27 | B28: El poder del lenguaje sin palabras | C28: Bárbara Tijerina | E28: Comunicación y marca personal | F28: 9
A29: 28 | B29: Habla para influenciar | C29: Brian Tracy | D29: Grijalbo | E29: Comunicación y marca personal | F29: 8
A30: 29 | B30: Hable como en TED | C30: Carmine Gallo | E30: Comunicación y marca personal | F30: 10
A31: 30 | B31: Ideas que pegan | C31: Chip Heath, Dan Heath | E31: Comunicación y marca personal | F31: 18
A32: 31 | B32: Imparable | C32: Sebastián Lora | D32: EXMA | E32: Comunicación y marca personal | F32: 9
A33: 32 | B33: Influencia y persuasión | C33: Guías HBR | E33: Comunicación y marca personal | F33: 13
A34: 33 | B34: La comunicación no verbal | C34: Flora Davis | E34: Comunicación y marca personal | F34: 22
A35: 34 | B35: La isla de los 5 faros | C35: Ferran Ramon-Cortés | E35: Comunicación y marca personal | F35: 8
A36: 35 | B36: Marketing personal | C36: Jorge E. Prieto Herrera | E36: Comunicación y marca personal | F36: 9
A37: 36 | B37: Neuro oratoria | C37: Jürgen Klaric | E37: Comunicación y marca personal | F37: 16
A38: 37 | B38: No me hables en ese tono | C38: Ricardo Gómez | E38: Comunicación y marca personal | F38: 11
A39: 38 | B39: Piensa rápido, habla mejor | C39: Matt Abrahams | D39: Océano | E39: Comunicación y marca personal | F39: 11
A40: 39 | B40: Storytelling contigo | D40: Knaflic | E40: Comunicación y marca personal | F40: 9 | I40: Confirmar autor
...

Sheet Resumen
A1: Categoría | B1: Cantidad
A2: Arte | B2: =COUNTIF(Catálogo!$E$2:$E$316,A2)
A3: Biografías | B3: =COUNTIF(Catálogo!$E$2:$E$316,A3)
A4: Ciencia y divulgación | B4: =COUNTIF(Catálogo!$E$2:$E$316,A4)
A5: Comunicación y marca personal | B5: =COUNTIF(Catálogo!$E$2:$E$316,A5)
A6: Creatividad e innovación | B6: =COUNTIF(Catálogo!$E$2:$E$316,A6)
A7: Datos y tecnología | B7: =COUNTIF(Catálogo!$E$2:$E$316,A7)
A8: Derecho | B8: =COUNTIF(Catálogo!$E$2:$E$316,A8)
A9: Desarrollo personal | B9: =COUNTIF(Catálogo!$E$2:$E$316,A9)
A10: Diseño | B10: =COUNTIF(Catálogo!$E$2:$E$316,A10)
A11: Economía y decisiones | B11: =COUNTIF(Catálogo!$E$2:$E$316,A11)
A12: Ensayo | B12: =COUNTIF(Catálogo!$E$2:$E$316,A12)
A13: Espiritualidad | B13: =COUNTIF(Catálogo!$E$2:$E$316,A13)
... A30: Sin identificar | B30: =COUNTIF(Catálogo!$E$2:$E$316,A30)
A31: TOTAL | B31: =SUM(B2:B30)
